Workbook
Name calendar: daygrid+[1]!firstdate-WEEKDAY([1]!firstdate)-weekday_option
Name Calendar_Year: #REF!
Name Calendar10Month: #REF!
Name Calendar10MonthOption: MATCH(Calendar10Month,months,0)
Name Calendar10Year: #REF!
Name Calendar11Month: #REF!
Name Calendar11MonthOption: MATCH(Calendar11Month,months,0)
Name Calendar11Year: #REF!
Name Calendar12Month: #REF!
Name Calendar12MonthOption: MATCH(Calendar12Month,months,0)
Name Calendar12Year: #REF!
Name Calendar1Month: #REF!
Name Calendar1MonthOption: MATCH(Calendar1Month,months,0)
Name Calendar1Year: #REF!
Name Calendar2Month: #REF!
Name Calendar2MonthOption: MATCH(Calendar2Month,months,0)
Name Calendar2Year: #REF!
Name Calendar3Month: #REF!
Name Calendar3MonthOption: MATCH(Calendar3Month,months,0)
Name Calendar3Year: #REF!
Name Calendar4Month: #REF!
Name Calendar4MonthOption: MATCH(Calendar4Month,months,0)
Name Calendar4Year: #REF!
Name Calendar5Month: #REF!
Name Calendar5MonthOption: MATCH(Calendar5Month,months,0)
Name Calendar5Year: #REF!
Name Calendar6Month: #REF!
Name Calendar6MonthOption: MATCH(Calendar6Month,months,0)
Name Calendar6Year: #REF!
Name Calendar7Month: #REF!
Name Calendar7MonthOption: MATCH(Calendar7Month,months,0)
Name Calendar7Year: #REF!
Name Calendar8Month: #REF!
Name Calendar8MonthOption: MATCH(Calendar8Month,months,0)
Name Calendar8Year: #REF!
Name Calendar9Month: #REF!
Name Calendar9MonthOption: MATCH(Calendar9Month,months,0)
Name Calendar9Year: #REF!
Name ColumnTitle3: #REF!
Name ColumnTitle4: #REF!
Name ColumnTitle5: #REF!
Name ColumnTitleRegion..AC22.1: #REF!
Name ColumnTitleRegion1..H12.1: #REF!
Name ColumnTitleRegion10..H54.1: #REF!
Name ColumnTitleRegion11..C56.1: #REF!
Name ColumnTitleRegion12..D56.1: #REF!
Name ColumnTitleRegion13..H68.1: #REF!
Name ColumnTitleRegion14..C70.1: #REF!
Name ColumnTitleRegion15..D70.1: #REF!
Name ColumnTitleRegion16..H82.1: #REF!
Name ColumnTitleRegion17..C84.1: #REF!
Name ColumnTitleRegion18..D84.1: #REF!
Name ColumnTitleRegion19..H96.1: #REF!
Name ColumnTitleRegion2..C14.1: #REF!
Name ColumnTitleRegion20..C98.1: #REF!
Name ColumnTitleRegion21..D98.1: #REF!
Name ColumnTitleRegion22..H110.1: #REF!
Name ColumnTitleRegion23..C112.1: #REF!
Name ColumnTitleRegion24..D112.1: #REF!
Name ColumnTitleRegion25..H124.1: #REF!

Sheet Store List
A1: Location | B1: Short Desc | C1: Description (THA) | D1: Area | E1: RSM/RM | F1: Area HR | G1: Area Manager | I1: ตำแหน่งภาษาอังกฤษ | J1: ตำแหน่งภาษาไทย
A2: 001 | B2: 1 | C2: ลาดพร้าว | D2: Area 5 | E2: Tanachai Boonsake | F2: Patnaree C. | G2: Pannawich P. | I2: SM-Accounting | J2: ผู้จัดการแผนกบัญชี
A3: 002 | B3: 2 | C3: แจ้งวัฒนะ | D3: Area 10 | E3: Tanagrid Juthapan | F3: Jeerakarn R. | G3: Tien-Hung Chou | I3: SM-SSS | J3: ผู้จัดการแผนกไอที
A4: 003 | B4: 3 | C4: ศรีนครินทร์ | D4: Area 11 | E4: Tanachai Boonsake | F4: Kittiphong M. | G4: Thitikarn P. | I4: SM-SSS & Accounting | J4: ผู้จัดการแผนกบัญชีและไอที
A5: 004 | B5: 4 | C5: บางบอน | D5: Area 1 | E5: Montree Yingyong | F5: Patnaree C. | G5: Sirada P. | I5: SM-Bakery | J5: ผู้จัดการแผนกเบเกอรี่
A6: 005 | B6: 5 | C6: ชลบุรี | D6: Area 9 | E6: Dujdaw Saengchan | F6: Jeerakarn R. | G6: Wattarapoo K. | I6: SM-Butchery | J6: ผู้จัดการแผนกเนื้อสัตว์
A7: 006 | B7: 6 | C7: เชียงใหม่ 1 | D7: Area 6 | E7: Tanawat Thavornseattawat | F7: Kittiphong M. | G7: Suphanan C. | I7: SM-CS | J7: ผู้จัดการแผนกบริการลูกค้า
A8: 007 | B8: 7 | C8: นครราชสีมา | D8: Area 2 | E8: Tanachai Boonsake | F8: Tanawat M. | G8: Pongsiri K. | I8: SM-DF1 | J8: ผู้จัดการแผนกสินค้าบริโภค 1
A9: 008 | B9: 8 | C9: รังสิต | D9: Area 11 | E9: Tanagrid Juthapan | F9: Kittiphong M. | G9: Thitikarn P. | I9: SM-DF2 | J9: ผู้จัดการแผนกสินค้าบริโภค 2
A10: 009 | B10: 9 | C10: หาดใหญ่ | D10: Area 4 | E10: Yongyoot Pattarawongjaleand | F10: Pramual L. | G10: Sanur C. | I10: SM-F&V | J10: ผู้จัดการแผนกผักและผลไม้
A11: 010 | B11: 10 | C11: อุดรธานี | D11: Area 7 | E11: Nattaphon Apisiriwatana | F11: Jutharat T. | G11: Chanpen B. | I11: SM-Fish | J11: ผู้จัดการแผนกปลา
A12: 011 | B12: 11 | C12: พิษณุโลก | D12: Area 2 | E12: Nattaphon Apisiriwatana | F12: Tanawat M. | G12: Pongsiri K. | I12: SM-Frozen | J12: ผู้จัดการแผนกอาหารแช่แข็ง
A13: 012 | B13: 12 | C13: ขอนแก่น | D13: Area 7 | E13: Nattaphon Apisiriwatana | F13: Jutharat T. | G13: Chanpen B. | I13: SM-General Affair | J13: ผู้จัดการแผนกซ่อมบำรุงและธุรการ
... A78: 077 | B78: 77 | C78: ละไม | D78: Area 12 | E78: Panwadee Pungperaporn | F78: Tanawat M. | G78: Jutaporn A. | I78: Sales Admin | J78: พนักงานธุรการแผนกขาย
A79: 078 | B79: 78 | C79: กัลปพฤกษ์ | D79: Area 1 | E79: Sedtharoj Theanthai | F79: Patnaree C. | G79: Sirada P.
A80: 079 | B80: 79 | C80: ยโสธร | D80: Area 8 | E80: Rattakate Prayunchat | F80: Jutharat T. | G80: Jieranai S.
A81: 080 | B81: 80 | C81: มหาสารคาม | D81: Area 8 | E81: Rattakate Prayunchat | F81: Jutharat T. | G81: Jieranai S.
A82: 081 | B82: 81 | C82: ฝาง | D82: Area 6 | E82: Tanawat Thavornseattawat | F82: Kittiphong M. | G82: Suphanan C.
A83: 082 | B83: 82 | C83: นครนายก | D83: Area 14 | E83: Jirayu Juthathap | F83: Jeerakarn R. | G83: Uraiwan N. | I83: Pass : 1234
A84: 083 | B84: 83 | C84: นครอินทร์ | D84: Area 11 | E84: Montree Yingyong | F84: Kittiphong M. | G84: Thitikarn P.
A85: 084 | B85: 84 | C85: บ้านเพ | D85: Area 14 | E85: Jirayu Juthathap | F85: Jeerakarn R. | G85: Uraiwan N.
A86: 085 | B86: 85 | C86: ทุ่งสง | D86: Area 4 | E86: Yongyoot Pattarawongjaleand | F86: Pramual L. | G86: Sanur C.
A87: 086 | B87: 86 | C87: ศรีนครินทร์ 2 | D87: Area 14 | E87: Sedtharoj Theanthai | F87: Jeerakarn R. | G87: Uraiwan N.
A88: 087 | B88: 87 | C88: พะเยา | D88: Area 6 | E88: Thanaphat Kaewphiboon | F88: Kittiphong M. | G88: Suphanan C.
A89: 089 | B89: 89 | C89: พิษณุโลก 2 | D89: Area 2 | E89: Nattaphon Apisiriwatana | F89: Tanawat M. | G89: Pongsiri K.
A90: 091 | B90: 91 | C90: สยามโฟรเซ่น ตลาดเมืองใหม่ | D90: Area 6 | F90: Kittiphong M. | G90: Suphanan C.
A91: 093 | B91: 93 | C91: สยามโฟรเซ่น ทุ่งสง | D91: Area 4 | F91: Pramual L. | G91: Sanur C.
A92: 095 | B92: 95 | C92: สยามโฟรเซ่น ศรีราชา | D92: Area 9 | F92: Jeerakarn R. | G92: Wattarapoo K.
A93: 096 | B93: 96 | C93: ทาวน์อินทาวน์ | D93: Area 3 | F93: Pornpan N. | G93: Kanda P.
A94: 100 | B94: 100 | C94: แพร่ | D94: Area 6 | E94: Thanaphat Kaewphiboon | F94: Kittiphong M. | G94: Suphanan C.
A95: 101 | B95: 101 | C95: เกาะช้าง | D95: Area 14 | E95: Jirayu Juthathap | F95: Jeerakarn R. | G95: Uraiwan N.
A96: 102 | B96: 102 | C96: นครราชสีมา 2 | D96: Area 2 | E96: Tanachai Boonsake | F96: Tanawat M. | G96: Pongsiri K.
A97: 103 | B97: 103 | C97: น่าน | D97: Area 6 | E97: Thanaphat Kaewphiboon | F97: Kittiphong M. | G97: Suphanan C.
A98: 104 | B98: 104 | C98: อ่าวนาง | D98: Area 12 | E98: Panwadee Pungperaporn | F98: Tanawat M. | G98: Jutaporn A.
A99: 105 | B99: 105 | C99: กะรน | D99: Area 12 | E99: Yuwarat Boonyothayarn | F99: Tanawat M. | G99: Jutaporn A.
A100: 106 | B100: 106 | C100: วารินชำราบ | D100: Area 8 | E100: Rattakate Prayunchat | F100: Jutharat T. | G100: Jieranai S.
A101: 107 | B101: 107 | C101: หนองบัวลำภู | D101: Area 7 | E101: Nattaphon Apisiriwatana | F101: Jutharat T. | G101: Chanpen B.
A102: 108 | B102: 108 | C102: หนองจอก | D102: Area 9 | E102: Wutipon Suprungrueng | F102: Jeerakarn R. | G102: Wattarapoo K.
A103: 109 | B103: 109 | C103: แหลมฉบัง | D103: Area 9 | E103: Dujdaw Saengchan | F103: Jeerakarn R. | G103: Wattarapoo K.
A104: 110 | B104: 110 | C104: ประจวบคีรีขันธ์ | D104: Area 3 | E104: Wutipon Suprungrueng | F104: Pornpan N. | G104: Kanda P.
...

Sheet Sheet3
A1: ตำแหน่งภาษาอังกฤษ | B1: ตำแหน่งภาษาไทย
A2: SM-Accounting | B2: แผนกบัญชี
A3: SM-SSS | B3: แผนกไอที
A4: SM-SSS & Accounting | B4: แผนกบัญชีและไอที
A5: SM-Bakery | B5: แผนกเบเกอรี่ | J5: Row Labels | K5: Count of ตำแหน่งภาษาไทย
A6: SM-Butchery | B6: แผนกเนื้อสัตว์ | J6: เลขานุการ | K6: 1
A7: SM-CS | B7: แผนกบริการลูกค้า | J7: พนักงานแคชเชียร์ | K7: 1
A8: SM-DF1 | B8: แผนกสินค้าบริโภค 1 | J8: พนักงานแผนก Non Food | K8: 1
A9: SM-DF2 | B9: แผนกสินค้าบริโภค 2 | J9: พนักงานแผนก Non Fresh | K9: 1
A10: SM-F&V | B10: แผนกผักและผลไม้ | J10: พนักงานแผนกเติมสินค้า | K10: 1
A11: SM-Fish | B11: แผนกปลา | J11: พนักงานแผนกเนื้อสัตว์ | K11: 1
A12: SM-Frozen | B12: แผนกอาหารแช่แข็ง | J12: พนักงานแผนกเบเกอรี่ | K12: 1
A13: SM-General Affair | B13: แผนกซ่อมบำรุงและธุรการ | J13: พนักงานแผนกจัดส่งสินค้า | K13: 1
A14: SM-Hub Mgr / SM OCS | B14: แผนกสั่งสินค้า | J14: พนักงานแผนกจัดออเดอร์สินค้า | K14: 1
A15: SM-Human Resources | B15: แผนกบุคคล | J15: พนักงานแผนกซ่อมบำรุง | K15: 1
A16: SM-NF | B16: แผนกอุปโภค | J16: พนักงานแผนกบุคคล | K16: 1
A17: SM-Non Fresh | B17: แผนกสินค้าอุปโภคบริโภค | J17: พนักงานแผนกปลา | K17: 1
... A31: Supv-Customer Service | B31: แผนกบริการลูกค้า | J31: พนักงานรับสินค้า | K31: 1
J32: (blank)
A33: Supv-DF2 | J33: แผนกบัญชี | K33: 2
A34: Supv-F&V | B34: แผนกผักและผลไม้ | D34: แผนกบัญชี | J34: แผนกไอที | K34: 2
A35: Supv-Fish | B35: แผนกปลา | D35: แผนกไอที | J35: แผนกบัญชีและไอที | K35: 1
A36: Supv-FR Club - Shop Setup | B36: แผนกขาย FR Club | D36: แผนกบัญชีและไอที | J36: แผนกเบเกอรี่ | K36: 2
A37: Supv-Fresh Food/Shop | B37: แผนกอาหารสด | D37: แผนกเบเกอรี่ | J37: แผนกเนื้อสัตว์ | K37: 2
A38: Supv-Frozen | B38: แผนกอาหารแช่แข็ง | D38: แผนกเนื้อสัตว์ | J38: แผนกบริการลูกค้า | K38: 2
A39: Supv-General Affair | B39: แผนกซ่อมบำรุง | D39: แผนกบริการลูกค้า | J39: แผนกสินค้าบริโภค 1 | K39: 1
A40: Supv-Last Mile | B40: แผนกขนส่งสินค้า | D40: แผนกสินค้าบริโภค 1 | J40: แผนกสินค้าบริโภค 2 | K40: 1
A41: Supv-NF1 | B41: แผนกสินค้าอุปโภค 1 | D41: แผนกสินค้าบริโภค 2 | J41: แผนกผักและผลไม้ | K41: 2
A42: Supv-NF2 | B42: แผนกสินค้าอุปโภค 2 | D42: แผนกผักและผลไม้ | J42: แผนกปลา | K42: 2
A43: Supv-Non Fresh | B43: แผนกสินค้า Non Fresh | D43: แผนกปลาและอาหารทะเล | J43: แผนกอาหารแช่แข็ง | K43: 2
A44: Supv-O2O Customer Service | B44: แผนกจัดออเดอร์สินค้า | D44: แผนกอาหารแช่แข็ง | J44: แผนกซ่อมบำรุงและธุรการ | K44: 1
A45: Supv-Operation GR | B45: แผนกตรวจรับสินค้า | D45: แผนกซ่อมบำรุงและธุรการ | J45: แผนกสั่งสินค้า | K45: 1
... A66: Staff-NF | B66: พนักงานแผนก Non Food | D66: แผนกความปลอดภัย | J66: ฝ่ายอาหารสด | K66: 1
A67: Staff-Non Fresh | B67: พนักงานแผนก Non Fresh | J67: ผู้ช่วยสาขา | K67: 1
A68: Staff-O2O Delivery | B68: พนักงานแผนกจัดส่งสินค้า | J68: ฝ่ายขายลูกค้าองค์กร | K68: 1
A69: Staff-O2O Operation | B69: พนักงานแผนกจัดออเดอร์สินค้า | J69: ผู้ช่วยสโตร์ฟู๊ดเซอร์วิส | K69: 1
A70: Staff-GR | B70: พนักงานรับสินค้า | J70: ทีมขาย | K70: 1
A71: SM-GR | B71: แผนกรับสินค้า | J71: ฝ่ายจัดออเดอร์สินค้าออนไลน์ | K71: 1
A72: OFM | B72: ฝ่ายจัดออเดอร์สินค้าออนไลน์ | J72: Grand Total | K72: 75
A73: Staff - Telesales | B73: พนักงานขายทางโทรศัพท์
...

Sheet ประกาศตำแหน่งงานว่างสาขา
A1: รหัสสาขา | B1: ชื่อสาขา | C1: ตำแหน่งงาน | D1: สถานะตำแหน่งงาน | E1: ตำแหน่งที่รับสมัคร
A2: 001 | B2: =IF(LEN(_xlfn.XLOOKUP($A2,'Store List'!$A:$A,'Store List'!$C:$C,"",0))=0,"",_xlfn.XLOOKUP($A2,'Store List'!$A:$A,'Store List'!$C:$C,"",0)) -> ลาดพร้าว | C2: SM-Accounting | D2: Open | E2: {=IF(LEN(_xlfn.XLOOKUP(T_2026[[#This Row],[ตำแหน่งงาน]],Table10[[#All],[ตำแหน่งภาษาอังกฤษ]],Table10[[#All],[ตำแหน่งภาษาไทย]],"",0))=0,"",_xlfn.XLOOKUP(T_2026[[#This Row],[ตำแหน่งงาน]],Table10[[#All],[ตำแหน่งภาษาอังกฤษ]],Table10[[#All],[ตำแหน่งภาษาไทย]],"",0))} -> ผู้จัดการแผนกบัญชี
A3: 002 | B3: =IF(LEN(_xlfn.XLOOKUP($A3,'Store List'!$A:$A,'Store List'!$C:$C,"",0))=0,"",_xlfn.XLOOKUP($A3,'Store List'!$A:$A,'Store List'!$C:$C,"",0)) -> แจ้งวัฒนะ | C3: SM-SSS & Accounting | D3: Closed | E3: {=IF(LEN(_xlfn.XLOOKUP(T_2026[[#This Row],[ตำแหน่งงาน]],Table10[[#All],[ตำแหน่งภาษาอังกฤษ]],Table10[[#All],[ตำแหน่งภาษาไทย]],"",0))=0,"",_xlfn.XLOOKUP(T_2026[[#This Row],[ตำแหน่งงาน]],Table10[[#All],[ตำแหน่งภาษาอังกฤษ]],Table10[[#All],[ตำแหน่งภาษาไทย]],"",0))} -> ผู้จัดการแผนกบัญชีและไอที
B4: =IF(LEN(_xlfn.XLOOKUP($A4,'Store List'!$A:$A,'Store List'!$C:$C,"",0))=0,"",_xlfn.XLOOKUP($A4,'Store List'!$A:$A,'Store List'!$C:$C,"",0)) | E4: {=IF(LEN(_xlfn.XLOOKUP(T_2026[[#This Row],[ตำแหน่งงาน]],Table10[[#All],[ตำแหน่งภาษาอังกฤษ]],Table10[[#All],[ตำแหน่งภาษาไทย]],"",0))=0,"",_xlfn.XLOOKUP(T_2026[[#This Row],[ตำแหน่งงาน]],Table10[[#All],[ตำแหน่งภาษาอังกฤษ]],Table10[[#All],[ตำแหน่งภาษาไทย]],"",0))}
B5: =IF(LEN(_xlfn.XLOOKUP($A5,'Store List'!$A:$A,'Store List'!$C:$C,"",0))=0,"",_xlfn.XLOOKUP($A5,'Store List'!$A:$A,'Store List'!$C:$C,"",0)) | E5: {=IF(LEN(_xlfn.XLOOKUP(T_2026[[#This Row],[ตำแหน่งงาน]],Table10[[#All],[ตำแหน่งภาษาอังกฤษ]],Table10[[#All],[ตำแหน่งภาษาไทย]],"",0))=0,"",_xlfn.XLOOKUP(T_2026[[#This Row],[ตำแหน่งงาน]],Table10[[#All],[ตำแหน่งภาษาอังกฤษ]],Table10[[#All],[ตำแหน่งภาษาไทย]],"",0))}
B6: =IF(LEN(_xlfn.XLOOKUP($A6,'Store List'!$A:$A,'Store List'!$C:$C,"",0))=0,"",_xlfn.XLOOKUP($A6,'Store List'!$A:$A,'Store List'!$C:$C,"",0)) | E6: {=IF(LEN(_xlfn.XLOOKUP(T_2026[[#This Row],[ตำแหน่งงาน]],Table10[[#All],[ตำแหน่งภาษาอังกฤษ]],Table10[[#All],[ตำแหน่งภาษาไทย]],"",0))=0,"",_xlfn.XLOOKUP(T_2026[[#This Row],[ตำแหน่งงาน]],Table10[[#All],[ตำแหน่งภาษาอังกฤษ]],Table10[[#All],[ตำแหน่งภาษาไทย]],"",0))}
B7: =IF(LEN(_xlfn.XLOOKUP($A7,'Store List'!$A:$A,'Store List'!$C:$C,"",0))=0,"",_xlfn.XLOOKUP($A7,'Store List'!$A:$A,'Store List'!$C:$C,"",0)) | E7: {=IF(LEN(_xlfn.XLOOKUP(T_2026[[#This Row],[ตำแหน่งงาน]],Table10[[#All],[ตำแหน่งภาษาอังกฤษ]],Table10[[#All],[ตำแหน่งภาษาไทย]],"",0))=0,"",_xlfn.XLOOKUP(T_2026[[#This Row],[ตำแหน่งงาน]],Table10[[#All],[ตำแหน่งภาษาอังกฤษ]],Table10[[#All],[ตำแหน่งภาษาไทย]],"",0))}
B8: =IF(LEN(_xlfn.XLOOKUP($A8,'Store List'!$A:$A,'Store List'!$C:$C,"",0))=0,"",_xlfn.XLOOKUP($A8,'Store List'!$A:$A,'Store List'!$C:$C,"",0)) | E8: {=IF(LEN(_xlfn.XLOOKUP(T_2026[[#This Row],[ตำแหน่งงาน]],Table10[[#All],[ตำแหน่งภาษาอังกฤษ]],Table10[[#All],[ตำแหน่งภาษาไทย]],"",0))=0,"",_xlfn.XLOOKUP(T_2026[[#This Row],[ตำแหน่งงาน]],Table10[[#All],[ตำแหน่งภาษาอังกฤษ]],Table10[[#All],[ตำแหน่งภาษาไทย]],"",0))}
B9: =IF(LEN(_xlfn.XLOOKUP($A9,'Store List'!$A:$A,'Store List'!$C:$C,"",0))=0,"",_xlfn.XLOOKUP($A9,'Store List'!$A:$A,'Store List'!$C:$C,"",0)) | E9: {=IF(LEN(_xlfn.XLOOKUP(T_2026[[#This Row],[ตำแหน่งงาน]],Table10[[#All],[ตำแหน่งภาษาอังกฤษ]],Table10[[#All],[ตำแหน่งภาษาไทย]],"",0))=0,"",_xlfn.XLOOKUP(T_2026[[#This Row],[ตำแหน่งงาน]],Table10[[#All],[ตำแหน่งภาษาอังกฤษ]],Table10[[#All],[ตำแหน่งภาษาไทย]],"",0))}
B10: =IF(LEN(_xlfn.XLOOKUP($A10,'Store List'!$A:$A,'Store List'!$C:$C,"",0))=0,"",_xlfn.XLOOKUP($A10,'Store List'!$A:$A,'Store List'!$C:$C,"",0)) | E10: {=IF(LEN(_xlfn.XLOOKUP(T_2026[[#This Row],[ตำแหน่งงาน]],Table10[[#All],[ตำแหน่งภาษาอังกฤษ]],Table10[[#All],[ตำแหน่งภาษาไทย]],"",0))=0,"",_xlfn.XLOOKUP(T_2026[[#This Row],[ตำแหน่งงาน]],Table10[[#All],[ตำแหน่งภาษาอังกฤษ]],Table10[[#All],[ตำแหน่งภาษาไทย]],"",0))}
B11: =IF(LEN(_xlfn.XLOOKUP($A11,'Store List'!$A:$A,'Store List'!$C:$C,"",0))=0,"",_xlfn.XLOOKUP($A11,'Store List'!$A:$A,'Store List'!$C:$C,"",0)) | E11: {=IF(LEN(_xlfn.XLOOKUP(T_2026[[#This Row],[ตำแหน่งงาน]],Table10[[#All],[ตำแหน่งภาษาอังกฤษ]],Table10[[#All],[ตำแหน่งภาษาไทย]],"",0))=0,"",_xlfn.XLOOKUP(T_2026[[#This Row],[ตำแหน่งงาน]],Table10[[#All],[ตำแหน่งภาษาอังกฤษ]],Table10[[#All],[ตำแหน่งภาษาไทย]],"",0))}
B12: =IF(LEN(_xlfn.XLOOKUP($A12,'Store List'!$A:$A,'Store List'!$C:$C,"",0))=0,"",_xlfn.XLOOKUP($A12,'Store List'!$A:$A,'Store List'!$C:$C,"",0)) | E12: {=IF(LEN(_xlfn.XLOOKUP(T_2026[[#This Row],[ตำแหน่งงาน]],Table10[[#All],[ตำแหน่งภาษาอังกฤษ]],Table10[[#All],[ตำแหน่งภาษาไทย]],"",0))=0,"",_xlfn.XLOOKUP(T_2026[[#This Row],[ตำแหน่งงาน]],Table10[[#All],[ตำแหน่งภาษาอังกฤษ]],Table10[[#All],[ตำแหน่งภาษาไทย]],"",0))}
B13: =IF(LEN(_xlfn.XLOOKUP($A13,'Store List'!$A:$A,'Store List'!$C:$C,"",0))=0,"",_xlfn.XLOOKUP($A13,'Store List'!$A:$A,'Store List'!$C:$C,"",0)) | E13: {=IF(LEN(_xlfn.XLOOKUP(T_2026[[#This Row],[ตำแหน่งงาน]],Table10[[#All],[ตำแหน่งภาษาอังกฤษ]],Table10[[#All],[ตำแหน่งภาษาไทย]],"",0))=0,"",_xlfn.XLOOKUP(T_2026[[#This Row],[ตำแหน่งงาน]],Table10[[#All],[ตำแหน่งภาษาอังกฤษ]],Table10[[#All],[ตำแหน่งภาษาไทย]],"",0))}
B14: =IF(LEN(_xlfn.XLOOKUP($A14,'Store List'!$A:$A,'Store List'!$C:$C,"",0))=0,"",_xlfn.XLOOKUP($A14,'Store List'!$A:$A,'Store List'!$C:$C,"",0)) | E14: {=IF(LEN(_xlfn.XLOOKUP(T_2026[[#This Row],[ตำแหน่งงาน]],Table10[[#All],[ตำแหน่งภาษาอังกฤษ]],Table10[[#All],[ตำแหน่งภาษาไทย]],"",0))=0,"",_xlfn.XLOOKUP(T_2026[[#This Row],[ตำแหน่งงาน]],Table10[[#All],[ตำแหน่งภาษาอังกฤษ]],Table10[[#All],[ตำแหน่งภาษาไทย]],"",0))}
B15: =IF(LEN(_xlfn.XLOOKUP($A15,'Store List'!$A:$A,'Store List'!$C:$C,"",0))=0,"",_xlfn.XLOOKUP($A15,'Store List'!$A:$A,'Store List'!$C:$C,"",0)) | E15: {=IF(LEN(_xlfn.XLOOKUP(T_2026[[#This Row],[ตำแหน่งงาน]],Table10[[#All],[ตำแหน่งภาษาอังกฤษ]],Table10[[#All],[ตำแหน่งภาษาไทย]],"",0))=0,"",_xlfn.XLOOKUP(T_2026[[#This Row],[ตำแหน่งงาน]],Table10[[#All],[ตำแหน่งภาษาอังกฤษ]],Table10[[#All],[ตำแหน่งภาษาไทย]],"",0))}
... B2233: =IF(LEN(_xlfn.XLOOKUP($A2233,'Store List'!$A:$A,'Store List'!$C:$C,"",0))=0,"",_xlfn.XLOOKUP($A2233,'Store List'!$A:$A,'Store List'!$C:$C,"",0)) | E2233: {=IF(LEN(_xlfn.XLOOKUP(T_2026[[#This Row],[ตำแหน่งงาน]],Table10[[#All],[ตำแหน่งภาษาอังกฤษ]],Table10[[#All],[ตำแหน่งภาษาไทย]],"",0))=0,"",_xlfn.XLOOKUP(T_2026[[#This Row],[ตำแหน่งงาน]],Table10[[#All],[ตำแหน่งภาษาอังกฤษ]],Table10[[#All],[ตำแหน่งภาษาไทย]],"",0))}
